Workbook

Sheet HOOFDBLAD
A1: Categorie | B1: Naam | C1: Link | D1: SheetId | E1: SortKey
A2: DEF VOORRAAD | B2: BB | DEF voorraad D&K | C2: Openen | D2: 1464683095 | E2: DEF VOORRAAD
A3: DEF VOORRAAD | B3: BB | DEF voorraad PICKUPS | C3: Openen | D3: 676878321 | E3: DEF VOORRAAD
A4: DEF VOORRAAD | B4: BB | DEF voorraad PLANTSOME | C4: Openen | D4: 1979170386 | E4: DEF VOORRAAD
A5: INPUT | B5: BB | Input - draaitable Pickups | C5: Openen | D5: 1542866148 | E5: INPUT
A6: INPUT | B6: BB | Input D&K | C6: Openen | D6: 1469470261 | E6: INPUT
A7: INPUT | B7: BB | Input PICKUPS | C7: Openen | D7: 0 | E7: INPUT
A8: INPUT | B8: BB | Input PLANTSOME | C8: Openen | D8: 359113496 | E8: INPUT
A9: OVERIG | B9: BB | D&K Draaitable | C9: Openen | D9: 1446350510 | E9: OVERIG
A10: OVERIG | B10: Detail3-ENSCHEDE DE WIECKSE | C10: Openen | D10: 1975234017 | E10: OVERIG
A11: OVERIG | B11: Draaitabel 3 | C11: Openen | D11: 2028403462 | E11: OVERIG
A12: OVERIG | B12: Email|data-w1 | C12: Openen | D12: 1385741807 | E12: OVERIG
A13: OVERIG | B13: GOUDA - Namelijst | C13: Openen | D13: 2121429765 | E13: OVERIG
... A41: TRANSPORT | B41: TR | Utrecht-STECK-27-11 | C41: Openen | D41: 1699637074 | E41: TRANSPORT

Sheet Totaaloverzicht D&K 2025-12-01 
A1: Categorie | B1: Verkocht | C1: Begin Voorraad | D1: Voorraad Resterend
A2: MET-100-125 | B2: 47 | C2: =IFERROR(VLOOKUP(A2,'BB | DEF voorraad D&K'!A:B,2,FALSE),0) -> 78 | D2: =C2-B2 -> 31
A3: MET-125-150 | B3: 80 | C3: =IFERROR(VLOOKUP(A3,'BB | DEF voorraad D&K'!A:B,2,FALSE),0) -> 85 | D3: =C3-B3 -> 5
A5: Total | B5: 127
A7: Grand Totaal | B7: 127

Sheet BB | Input PICKUPS
A1: Line: SKU | B1: Additional Details | C1: Pickup-Day | D1: Pickup-Date | E1: Pickup-Time | F1: Pickup-Location-Company | G1: Name | H1: Line: Variant SKU | I1: ID | J1: Tags | K1: Line: Product Type | L1: Line: Name | M1: Line: Quantity | N1: Line: Product Handle | O1: Line: Title | P1: Line: Fulfillment Status | Q1: Line: Type | R1: Line: ID | S1: Order Fulfillment Status | T1: Note | U1: Fulfillment: Status | V1: Boomtype
A2: UTRECHT-STECK-BOOM-MET-BORG-150-175 | B2: Pickup-Location-Id: 302654 Pickup-Day: saturday Pickup-Date: 2025/11/29 Pickup-Location-Company: UTRECHT - Steck Pickup-Location-Address-Line-1: Gageldijk 3 Pickup-Location-City: Utrecht Pickup-Location-Postal-Code: 3566 ME Pickup-Location-Country: Netherlands Checkout-Method: pickup Pickup-Time: | C2: saturday | D2: 45990 | F2: UTRECHT - Steck | G2: #BB-25-6886 | H2: UTRECHT-STECK-BOOM-MET-BORG-150-175 | I2: 10399266046275 | J2: 29-11-2025, Pickup Order, Saturday, UTRECHT-STECK | L2: Utrecht Steck - BB met kluit (incl. €10 borg) - 150-175 cm | M2: 1 | N2: ut-vandestreek-boom-met-borg | O2: Utrecht Steck - BB met kluit (incl. €10 borg) | P2: fulfilled | Q2: Line Item | R2: 32610112209219 | S2: fulfilled | V2: MET-150-175
A3: UTRECHT-STECK-BOOM-MET-BORG-175-200 | B3: Pickup-Location-Id: 302654 Pickup-Day: saturday Pickup-Date: 2025/11/29 Pickup-Location-Company: UTRECHT - Steck Pickup-Location-Address-Line-1: Gageldijk 3 Pickup-Location-City: Utrecht Pickup-Location-Postal-Code: 3566 ME Pickup-Location-Country: Netherlands Checkout-Method: pickup Pickup-Time: | C3: saturday | D3: 45990 | F3: UTRECHT - Steck | G3: #BB-25-6906 | H3: UTRECHT-STECK-BOOM-MET-BORG-175-200 | I3: 10406955221315 | J3: 29-11-2025, Pickup Order, Saturday, UTRECHT-STECK | L3: Utrecht Steck - BB met kluit (incl. €10 borg) - 175-200 cm | M3: 1 | N3: ut-vandestreek-boom-met-borg | O3: Utrecht Steck - BB met kluit (incl. €10 borg) | P3: fulfilled | Q3: Line Item | R3: 32629987901763 | S3: fulfilled | V3: MET-175-200
A4: UTRECHT-STECK-BOOM-MET-BORG-125-150 | B4: Pickup-Location-Id: 302654 Pickup-Day: saturday Pickup-Date: 2025/11/29 Pickup-Location-Company: UTRECHT - Steck Pickup-Location-Address-Line-1: Gageldijk 3 Pickup-Location-City: Utrecht Pickup-Location-Postal-Code: 3566 ME Pickup-Location-Country: Netherlands Checkout-Method: pickup Pickup-Time: | C4: saturday | D4: 45990 | F4: UTRECHT - Steck | G4: #BB-25-6917 | H4: UTRECHT-STECK-BOOM-MET-BORG-125-150 | I4: 10408696578371 | J4: 29-11-2025, Pickup Order, Saturday, UTRECHT-STECK | L4: Utrecht Steck - BB met kluit (incl. €10 borg) - 125-150 cm | M4: 1 | N4: ut-vandestreek-boom-met-borg | O4: Utrecht Steck - BB met kluit (incl. €10 borg) | P4: fulfilled | Q4: Line Item | R4: 32633448399171 | S4: fulfilled | V4: MET-125-150
A5: UTRECHT-STECK-BOOM-ZONDER-150-175 | B5: Pickup-Location-Id: 302654 Pickup-Day: saturday Pickup-Date: 2025/11/29 Pickup-Location-Company: UTRECHT - Steck Pickup-Location-Address-Line-1: Gageldijk 3 Pickup-Location-City: Utrecht Pickup-Location-Postal-Code: 3566 ME Pickup-Location-Country: Netherlands Checkout-Method: pickup Pickup-Time: | C5: saturday | D5: 45990 | F5: UTRECHT - Steck | G5: #BB-25-6949 | H5: UTRECHT-STECK-BOOM-ZONDER-150-175 | I5: 10413020873027 | J5: 29-11-2025, Pickup Order, Saturday, UTRECHT-STECK, WAKE-UP | L5: Utrecht Steck - BB zonder kluit - 150-175 cm | M5: 1 | N5: ut-vandestreek-boom-zonder | O5: Utrecht Steck - BB zonder kluit | P5: fulfilled | Q5: Line Item | R5: 32642203189571 | S5: fulfilled | V5: ZONDER-150-175
A6: UTRECHT-STECK-BOOM-MET-BORG-150-175 | B6: Pickup-Location-Id: 302654 Pickup-Day: saturday Pickup-Date: 2025/11/29 Pickup-Location-Company: UTRECHT - Steck Pickup-Location-Address-Line-1: Gageldijk 3 Pickup-Location-City: Utrecht Pickup-Location-Postal-Code: 3566 ME Pickup-Location-Country: Netherlands Checkout-Method: pickup Pickup-Time: | C6: saturday | D6: 45990 | F6: UTRECHT - Steck | G6: #BB-25-6954 | H6: UTRECHT-STECK-BOOM-MET-BORG-150-175 | I6: 10414036320579 | J6: 29-11-2025, Pickup Order, Saturday, UTRECHT-STECK, WAKE-UP | L6: Utrecht Steck - BB met kluit (incl. €10 borg) - 150-175 cm | M6: 1 | N6: ut-vandestreek-boom-met-borg | O6: Utrecht Steck - BB met kluit (incl. €10 borg) | P6: fulfilled | Q6: Line Item | R6: 32644273996099 | S6: fulfilled | V6: MET-150-175
A7: UTRECHT-STECK-BOOM-MET-BORG-125-150 | B7: Pickup-Location-Id: 302654 Pickup-Day: saturday Pickup-Date: 2025/11/29 Pickup-Location-Company: UTRECHT - Steck Pickup-Location-Address-Line-1: Gageldijk 3 Pickup-Location-City: Utrecht Pickup-Location-Postal-Code: 3566 ME Pickup-Location-Country: Netherlands Checkout-Method: pickup Pickup-Time: | C7: saturday | D7: 45990 | F7: UTRECHT - Steck | G7: #BB-25-6971 | H7: UTRECHT-STECK-BOOM-MET-BORG-125-150 | I7: 10419122635075 | J7: 29-11-2025, Pickup Order, Saturday, UTRECHT-STECK, WAKE-UP | L7: Utrecht Steck - BB met kluit (incl. €10 borg) - 125-150 cm | M7: 1 | N7: ut-vandestreek-boom-met-borg | O7: Utrecht Steck - BB met kluit (incl. €10 borg) | P7: fulfilled | Q7: Line Item | R7: 32657251434819 | S7: fulfilled | V7: MET-125-150
A8: GOUDA-STADSKANT-BOOM-MET-BORG-100-125 | B8: Pickup-Location-Id: 278027 Pickup-Day: saturday Pickup-Date: 2025/11/29 Pickup-Time: 12\:45 PM Pickup-Location-Company: GOUDA - Stadskant Pickup-Location-Address-Line-1: Agnietenstraat 19 Pickup-Location-City: Gouda Pickup-Location-Postal-Code: 2801 GH Pickup-Location-Country: Netherlands Checkout-Method: pickup | C8: saturday | D8: 45990 | E8: 12\:45 PM | F8: GOUDA - Stadskant | G8: #BB-25-7005 | H8: GOUDA-STADSKANT-BOOM-MET-BORG-100-125 | I8: 10424394940739 | J8: 12:45, 29-11-2025, GOUDA, Pickup Order, Saturday, WAKE-UP | L8: Gouda Stadskant - BB met kluit (incl. €10 borg) - 100-125 cm | M8: 1 | N8: gd-stadskant-boom-met-borg | O8: Gouda Stadskant - BB met kluit (incl. €10 borg) | P8: fulfilled | Q8: Line Item | R8: 32668014674243 | S8: fulfilled | V8: MET-100-125
A9: UTRECHT-STECK-BOOM-MET-BORG-125-150 | B9: Pickup-Location-Id: 302654 Pickup-Day: saturday Pickup-Date: 2025/11/29 Pickup-Location-Company: UTRECHT - Steck Pickup-Location-Address-Line-1: Gageldijk 3 Pickup-Location-City: Utrecht Pickup-Location-Postal-Code: 3566 ME Pickup-Location-Country: Netherlands Checkout-Method: pickup Pickup-Time: | C9: saturday | D9: 45990 | F9: UTRECHT - Steck | G9: #BB-25-7007 | H9: UTRECHT-STECK-BOOM-MET-BORG-125-150 | I9: 10424775803203 | J9: 29-11-2025, Pickup Order, Saturday, UTRECHT-STECK, WAKE-UP | L9: Utrecht Steck - BB met kluit (incl. €10 borg) - 125-150 cm | M9: 1 | N9: ut-vandestreek-boom-met-borg | O9: Utrecht Steck - BB met kluit (incl. €10 borg) | P9: fulfilled | Q9: Line Item | R9: 32668830531907 | S9: fulfilled | V9: MET-125-150
A10: GOUDA-STADSKANT-BOOM-MET-BORG-100-125 | B10: Pickup-Location-Id: 278027 Pickup-Day: saturday Pickup-Date: 2025/11/29 Pickup-Time: 3\:45 PM Pickup-Location-Company: GOUDA - Stadskant Pickup-Location-Address-Line-1: Agnietenstraat 19 Pickup-Location-City: Gouda Pickup-Location-Postal-Code: 2801 GH Pickup-Location-Country: Netherlands Checkout-Method: pickup | C10: saturday | D10: 45990 | E10: 3\:45 PM | F10: GOUDA - Stadskant | G10: #BB-25-7024 | H10: GOUDA-STADSKANT-BOOM-MET-BORG-100-125 | I10: 10427177795907 | J10: 15:45, 29-11-2025, GOUDA, Pickup Order, Saturday, WAKE-UP | L10: Gouda Stadskant - BB met kluit (incl. €10 borg) - 100-125 cm | M10: 1 | N10: gd-stadskant-boom-met-borg | O10: Gouda Stadskant - BB met kluit (incl. €10 borg) | P10: fulfilled | Q10: Line Item | R10: 32674036547907 | S10: fulfilled | V10: MET-100-125
A11: UTRECHT-STECK-BOOM-MET-BORG-125-150 | B11: Pickup-Location-Id: 302654 Pickup-Day: saturday Pickup-Date: 2025/11/29 Pickup-Location-Company: UTRECHT - Steck Pickup-Location-Address-Line-1: Gageldijk 3 Pickup-Location-City: Utrecht Pickup-Location-Postal-Code: 3566 ME Pickup-Location-Country: Netherlands Checkout-Method: pickup Pickup-Time: | C11: saturday | D11: 45990 | F11: UTRECHT - Steck | G11: #BB-25-7077 | H11: UTRECHT-STECK-BOOM-MET-BORG-125-150 | I11: 10432715096387 | J11: 29-11-2025, Pickup Order, Saturday, UTRECHT-STECK, WAKE-UP | L11: Utrecht Steck - BB met kluit (incl. €10 borg) - 125-150 cm | M11: 1 | N11: ut-vandestreek-boom-met-borg | O11: Utrecht Steck - BB met kluit (incl. €10 borg) | P11: fulfilled | Q11: Line Item | R11: 32686194884931 | S11: fulfilled | V11: MET-125-150
A12: UTRECHT-STECK-BOOM-MET-BORG-150-175 | B12: Pickup-Location-Id: 302654 Pickup-Day: saturday Pickup-Date: 2025/11/29 Pickup-Location-Company: UTRECHT - Steck Pickup-Location-Address-Line-1: Gageldijk 3 Pickup-Location-City: Utrecht Pickup-Location-Postal-Code: 3566 ME Pickup-Location-Country: Netherlands Checkout-Method: pickup Pickup-Time: | C12: saturday | D12: 45990 | F12: UTRECHT - Steck | G12: #BB-25-7090 | H12: UTRECHT-STECK-BOOM-MET-BORG-150-175 | I12: 10433588560195 | J12: 29-11-2025, Pickup Order, Saturday, UTRECHT-STECK, WAKE-UP | L12: Utrecht Steck - BB met kluit (incl. €10 borg) - 150-175 cm | M12: 1 | N12: ut-vandestreek-boom-met-borg | O12: Utrecht Steck - BB met kluit (incl. €10 borg) | P12: fulfilled | Q12: Line Item | R12: 32688101622083 | S12: fulfilled | V12: MET-150-175
A13: UTRECHT-STECK-BOOM-ZONDER-175-200 | B13: Pickup-Location-Id: 302654 Pickup-Day: saturday Pickup-Date: 2025/11/29 Pickup-Location-Company: UTRECHT - Steck Pickup-Location-Address-Line-1: Gageldijk 3 Pickup-Location-City: Utrecht Pickup-Location-Postal-Code: 3566 ME Pickup-Location-Country: Netherlands Checkout-Method: pickup Pickup-Time: | C13: saturday | D13: 45990 | F13: UTRECHT - Steck | G13: #BB-25-7203 | H13: UTRECHT-STECK-BOOM-ZONDER-175-200 | I13: 10436825284931 | J13: 29-11-2025, Pickup Order, Saturday, UTRECHT-STECK, WAKE-UP | L13: Utrecht Steck - BB zonder kluit - 175-200 cm | M13: 1 | N13: ut-vandestreek-boom-zonder | O13: Utrecht Steck - BB zonder kluit | P13: fulfilled | Q13: Line Item | R13: 32695174299971 | S13: fulfilled | V13: ZONDER-175-200
A14: UTRECHT-STECK-BOOM-MET-BORG-125-150 | B14: Pickup-Location-Id: 302654 Pickup-Day: saturday Pickup-Date: 2025/11/29 Pickup-Location-Company: UTRECHT - Steck Pickup-Location-Address-Line-1: Gageldijk 3 Pickup-Location-City: Utrecht Pickup-Location-Postal-Code: 3566 ME Pickup-Location-Country: Netherlands Checkout-Method: pickup Pickup-Time: | C14: saturday | D14: 45990 | F14: UTRECHT - Steck | G14: #BB-25-7192 | H14: UTRECHT-STECK-BOOM-MET-BORG-125-150 | I14: 10436736745795 | J14: 29-11-2025, Pickup Order, Saturday, UTRECHT-STECK, WAKE-UP | L14: Utrecht Steck - BB met kluit (incl. €10 borg) - 125-150 cm | M14: 1 | N14: ut-vandestreek-boom-met-borg | O14: Utrecht Steck - BB met kluit (incl. €10 borg) | P14: fulfilled | Q14: Line Item | R14: 32694985556291 | S14: fulfilled | V14: MET-125-150
A15: UTRECHT-STECK-BOOM-ZONDER-250-300 | B15: Pickup-Location-Id: 302654 Pickup-Day: saturday Pickup-Date: 2025/11/29 Pickup-Location-Company: UTRECHT - Steck Pickup-Location-Address-Line-1: Gageldijk 3 Pickup-Location-City: Utrecht Pickup-Location-Postal-Code: 3566 ME Pickup-Location-Country: Netherlands Checkout-Method: pickup Pickup-Time: | C15: saturday | D15: 45990 | F15: UTRECHT - Steck | G15: #BB-25-7238 | H15: UTRECHT-STECK-BOOM-ZONDER-250-300 | I15: 10437126816067 | J15: 29-11-2025, Pickup Order, Saturday, UTRECHT-STECK, WAKE-UP | L15: Utrecht Steck - BB zonder kluit - 250-300 cm | M15: 1 | N15: ut-vandestreek-boom-zonder | O15: Utrecht Steck - BB zonder kluit | P15: fulfilled | Q15: Line Item | R15: 32695836410179 | S15: fulfilled | V15: ZONDER-250-300
A16: UTRECHT-STECK-BOOM-MET-BORG-125-150 | B16: Pickup-Location-Id: 302654 Pickup-Day: saturday Pickup-Date: 2025/11/29 Pickup-Time: 11\:00 AM Pickup-Location-Company: UTRECHT - Steck Pickup-Location-Address-Line-1: Gageldijk 3 Pickup-Location-City: Utrecht Pickup-Location-Postal-Code: 3566 ME Pickup-Location-Country: Netherlands Checkout-Method: pickup | C16: saturday | D16: 45990 | E16: 11\:00 AM | F16: UTRECHT - Steck | G16: #BB-25-7390 | H16: UTRECHT-STECK-BOOM-MET-BORG-125-150 | I16: 10440909881667 | J16: 11:00, 29-11-2025, Pickup Order, Saturday, UTRECHT-STECK, WAKE-UP | L16: Utrecht Steck - BB met kluit (incl. €10 borg) - 125-150 cm | M16: 1 | N16: ut-vandestreek-boom-met-borg | O16: Utrecht Steck - BB met kluit (incl. €10 borg) | P16: fulfilled | Q16: Line Item | R16: 32704053248323 | S16: fulfilled | V16: MET-125-150
A17: UTRECHT-STECK-BOOM-MET-BORG-125-150 | B17: Pickup-Location-Id: 302654 Pickup-Day: saturday Pickup-Date: 2025/11/29 Pickup-Time: 10\:30 AM Pickup-Location-Company: UTRECHT - Steck Pickup-Location-Address-Line-1: Gageldijk 3 Pickup-Location-City: Utrecht Pickup-Location-Postal-Code: 3566 ME Pickup-Location-Country: Netherlands Checkout-Method: pickup | C17: saturday | D17: 45990 | E17: 10\:30 AM | F17: UTRECHT - Steck | G17: #BB-25-7477 | H17: UTRECHT-STECK-BOOM-MET-BORG-125-150 | I17: 10445230309699 | J17: 10:30, 29-11-2025, Pickup Order, Saturday, UTRECHT-STECK, WAKE-UP | L17: Utrecht Steck - BB met kluit (incl. €10 borg) - 125-150 cm | M17: 1 | N17: ut-vandestreek-boom-met-borg | O17: Utrecht Steck - BB met kluit (incl. €10 borg) | P17: fulfilled | Q17: Line Item | R17: 32716408226115 | S17: fulfilled | V17: MET-125-150
A18: UTRECHT-STECK-BOOM-MET-BORG-100-125 | B18: Pickup-Location-Id: 302654 Pickup-Day: saturday Pickup-Date: 2025/11/29 Pickup-Time: 11\:00 AM Pickup-Location-Company: UTRECHT - Steck Pickup-Location-Address-Line-1: Gageldijk 3 Pickup-Location-City: Utrecht Pickup-Location-Postal-Code: 3566 ME Pickup-Location-Country: Netherlands Checkout-Method: pickup | C18: saturday | D18: 45990 | E18: 11\:00 AM | F18: UTRECHT - Steck | G18: #BB-25-7542 | H18: UTRECHT-STECK-BOOM-MET-BORG-100-125 | I18: 10448258072899 | J18: 11:00, 29-11-2025, Pickup Order, Saturday, UTRECHT-STECK, WAKE-UP | L18: Utrecht Steck - BB met kluit (incl. €10 borg) - 100-125 cm | M18: 1 | N18: ut-vandestreek-boom-met-borg | O18: Utrecht Steck - BB met kluit (incl. €10 borg) | P18: fulfilled | Q18: Line Item | R18: 32723737674051 | S18: fulfilled | V18: MET-100-125
A19: UTRECHT-STECK-BOOM-MET-BORG-100-125 | B19: Pickup-Location-Id: 302654 Pickup-Day: saturday Pickup-Date: 2025/11/29 Pickup-Time: 11\:30 AM Pickup-Location-Company: UTRECHT - Steck Pickup-Location-Address-Line-1: Gageldijk 3 Pickup-Location-City: Utrecht Pickup-Location-Postal-Code: 3566 ME Pickup-Location-Country: Netherlands Checkout-Method: pickup | C19: saturday | D19: 45990 | E19: 11\:30 AM | F19: UTRECHT - Steck | G19: #BB-25-7596 | H19: UTRECHT-STECK-BOOM-MET-BORG-100-125 | I19: 10449573937475 | J19: 11:30, 29-11-2025, Pickup Order, Saturday, UTRECHT-STECK, WAKE-UP | L19: Utrecht Steck - BB met kluit (incl. €10 borg) - 100-125 cm | M19: 1 | N19: ut-vandestreek-boom-met-borg | O19: Utrecht Steck - BB met kluit (incl. €10 borg) | P19: fulfilled | Q19: Line Item | R19: 32726730735939 | S19: fulfilled | V19: MET-100-125
A20: UTRECHT-STECK-BOOM-ZONDER-150-175 | B20: Pickup-Location-Id: 302654 Pickup-Day: saturday Pickup-Date: 2025/11/29 Pickup-Time: 12\:00 PM Pickup-Location-Company: UTRECHT - Steck Pickup-Location-Address-Line-1: Gageldijk 3 Pickup-Location-City: Utrecht Pickup-Location-Postal-Code: 3566 ME Pickup-Location-Country: Netherlands Checkout-Method: pickup | C20: saturday | D20: 45990 | E20: 12\:00 PM | F20: UTRECHT - Steck | G20: #BB-25-7607 | H20: UTRECHT-STECK-BOOM-ZONDER-150-175 | I20: 10449865212227 | J20: 12:00, 29-11-2025, Pickup Order, Saturday, UTRECHT-STECK, WAKE-UP | L20: Utrecht Steck - BB zonder kluit - 150-175 cm | M20: 1 | N20: ut-vandestreek-boom-zonder | O20: Utrecht Steck - BB zonder kluit | P20: fulfilled | Q20: Line Item | R20: 32727416144195 | S20: fulfilled | V20: ZONDER-150-175
A21: UTRECHT-STECK-BOOM-MET-BORG-150-175 | B21: Pickup-Location-Id: 302654 Pickup-Day: saturday Pickup-Date: 2025/11/29 Pickup-Time: 10\:00 AM Pickup-Location-Company: UTRECHT - Steck Pickup-Location-Address-Line-1: Gageldijk 3 Pickup-Location-City: Utrecht Pickup-Location-Postal-Code: 3566 ME Pickup-Location-Country: Netherlands Checkout-Method: pickup | C21: saturday | D21: 45990 | E21: 10\:00 AM | F21: UTRECHT - Steck | G21: #BB-25-7637 | H21: UTRECHT-STECK-BOOM-MET-BORG-150-175 | I21: 10450714460483 | J21: 10:00, 29-11-2025, Pickup Order, Saturday, UTRECHT-STECK, WAKE-UP | L21: Utrecht Steck - BB met kluit (incl. €10 borg) - 150-175 cm | M21: 1 | N21: ut-vandestreek-boom-met-borg | O21: Utrecht Steck - BB met kluit (incl. €10 borg) | P21: fulfilled | Q21: Line Item | R21: 32729372229955 | S21: fulfilled | V21: MET-150-175
A22: UTRECHT-STECK-BOOM-MET-BORG-150-175 | B22: Pickup-Location-Id: 302654 Pickup-Day: saturday Pickup-Date: 2025/11/29 Pickup-Time: 11\:00 AM Pickup-Location-Company: UTRECHT - Steck Pickup-Location-Address-Line-1: Gageldijk 3 Pickup-Location-City: Utrecht Pickup-Location-Postal-Code: 3566 ME Pickup-Location-Country: Netherlands Checkout-Method: pickup | C22: saturday | D22: 45990 | E22: 11\:00 AM | F22: UTRECHT - Steck | G22: #BB-25-7636 | H22: UTRECHT-STECK-BOOM-MET-BORG-150-175 | I22: 10450709545283 | J22: 11:00, 29-11-2025, Pickup Order, Saturday, UTRECHT-STECK, WAKE-UP | L22: Utrecht Steck - BB met kluit (incl. €10 borg) - 150-175 cm | M22: 1 | N22: ut-vandestreek-boom-met-borg | O22: Utrecht Steck - BB met kluit (incl. €10 borg) | P22: fulfilled | Q22: Line Item | R22: 32729360335171 | S22: fulfilled | V22: MET-150-175
A23: UTRECHT-STECK-BOOM-ZONDER-150-175 | B23: Pickup-Location-Id: 302654 Pickup-Day: saturday Pickup-Date: 2025/11/29 Pickup-Time: 12\:00 PM Pickup-Location-Company: UTRECHT - Steck Pickup-Location-Address-Line-1: Gageldijk 3 Pickup-Location-City: Utrecht Pickup-Location-Postal-Code: 3566 ME Pickup-Location-Country: Netherlands Checkout-Method: pickup | C23: saturday | D23: 45990 | E23: 12\:00 PM | F23: UTRECHT - Steck | G23: #BB-25-7688 | H23: UTRECHT-STECK-BOOM-ZONDER-150-175 | I23: 10451223740739 | J23: 12:00, 29-11-2025, Pickup Order, Saturday, UTRECHT-STECK, WAKE-UP | L23: Utrecht Steck - BB zonder kluit - 150-175 cm | M23: 1 | N23: ut-vandestreek-boom-zonder | O23: Utrecht Steck - BB zonder kluit | P23: fulfilled | Q23: Line Item | R23: 32730488013123 | S23: fulfilled | V23: ZONDER-150-175
A24: GOUDA-STADSKANT-BOOM-ZONDER-175-200 | B24: Pickup-Location-Id: 278027 Pickup-Day: saturday Pickup-Date: 2025/11/29 Pickup-Time: 2\:45 PM Pickup-Location-Company: GOUDA - Stadskant Pickup-Location-Address-Line-1: Agnietenstraat 19 Pickup-Location-City: Gouda Pickup-Location-Postal-Code: 2801 GH Pickup-Location-Country: Netherlands Checkout-Method: pickup | C24: saturday | D24: 45990 | E24: 2\:45 PM | F24: GOUDA - Stadskant | G24: #BB-25-7785 | H24: GOUDA-STADSKANT-BOOM-ZONDER-175-200 | I24: 10451648479555 | J24: 14:45, 29-11-2025, GOUDA, Pickup Order, Saturday, WAKE-UP | L24: Gouda Stadskant - BB zonder kluit - 175-200 cm | M24: 1 | N24: gd-stadskant-boom-zonder | O24: Gouda Stadskant - BB zonder kluit | P24: fulfilled | Q24: Line Item | R24: 32731453555011 | S24: fulfilled | V24: ZONDER-175-200
A25: GOUDA-STADSKANT-BOOM-MET-BORG-125-150 | B25: Pickup-Location-Id: 278027 Pickup-Day: saturday Pickup-Date: 2025/11/29 Pickup-Time: 2\:15 PM Pickup-Location-Company: GOUDA - Stadskant Pickup-Location-Address-Line-1: Agnietenstraat 19 Pickup-Location-City: Gouda Pickup-Location-Postal-Code: 2801 GH Pickup-Location-Country: Netherlands Checkout-Method: pickup | C25: saturday | D25: 45990 | E25: 2\:15 PM | F25: GOUDA - Stadskant | G25: #BB-25-7808 | H25: GOUDA-STADSKANT-BOOM-MET-BORG-125-150 | I25: 10451855900995 | J25: 14:15, 29-11-2025, GOUDA, Pickup Order, Saturday, WAKE-UP | L25: Gouda Stadskant - BB met kluit (incl. €10 borg) - 125-150 cm | M25: 1 | N25: gd-stadskant-boom-met-borg | O25: Gouda Stadskant - BB met kluit (incl. €10 borg) | P25: fulfilled | Q25: Line Item | R25: 32731916697923 | S25: fulfilled | V25: MET-125-150
A26: UTRECHT-STECK-BOOM-ZONDER-200-250 | B26: Pickup-Location-Id: 302654 Pickup-Day: saturday Pickup-Date: 2025/11/29 Pickup-Time: 10\:30 AM Pickup-Location-Company: UTRECHT - Steck Pickup-Location-Address-Line-1: Gageldijk 3 Pickup-Location-City: Utrecht Pickup-Location-Postal-Code: 3566 ME Pickup-Location-Country: Netherlands Checkout-Method: pickup | C26: saturday | D26: 45990 | E26: 10\:30 AM | F26: UTRECHT - Steck | G26: #BB-25-7892 | H26: UTRECHT-STECK-BOOM-ZONDER-200-250 | I26: 10452688666947 | J26: 10:30, 29-11-2025, Pickup Order, Saturday, UTRECHT-STECK, WAKE-UP | L26: Utrecht Steck - BB zonder kluit - 200-250 cm | M26: 1 | N26: ut-vandestreek-boom-zonder | O26: Utrecht Steck - BB zonder kluit | P26: fulfilled | Q26: Line Item | R26: 32733898375491 | S26: fulfilled | V26: ZONDER-200-250
A27: GOUDA-STADSKANT-BOOM-MET-BORG-125-150 | B27: Pickup-Location-Id: 278027 Pickup-Day: saturday Pickup-Date: 2025/11/29 Pickup-Time: 11\:15 AM Pickup-Location-Company: GOUDA - Stadskant Pickup-Location-Address-Line-1: Agnietenstraat 19 Pickup-Location-City: Gouda Pickup-Location-Postal-Code: 2801 GH Pickup-Location-Country: Netherlands Checkout-Method: pickup | C27: saturday | D27: 45990 | E27: 11\:15 AM | F27: GOUDA - Stadskant | G27: #BB-25-7934 | H27: GOUDA-STADSKANT-BOOM-MET-BORG-125-150 | I27: 10453310079299 | J27: 11:15, 29-11-2025, GOUDA, Pickup Order, Saturday, WAKE-UP | L27: Gouda Stadskant - BB met kluit (incl. €10 borg) - 125-150 cm | M27: 1 | N27: gd-stadskant-boom-met-borg | O27: Gouda Stadskant - BB met kluit (incl. €10 borg) | P27: fulfilled | Q27: Line Item | R27: 32735315493187 | S27: fulfilled | V27: MET-125-150
... A62: UTRECHT-STECK-BOOM-MET-BORG-125-150 | B62: Pickup-Location-Id: 302654 Pickup-Day: saturday Pickup-Date: 2025/11/29 Pickup-Time: 4\:00 PM Pickup-Location-Company: UTRECHT - Steck Pickup-Location-Address-Line-1: Gageldijk 3 Pickup-Location-City: Utrecht Pickup-Location-Postal-Code: 3566 ME Pickup-Location-Country: Netherlands Checkout-Method: pickup | C62: saturday | D62: 45990 | E62: 4\:00 PM | F62: UTRECHT - Steck | G62: #BB-25-9522 | H62: UTRECHT-STECK-BOOM-MET-BORG-125-150 | I62: 10486846193987 | J62: 16:00, 29-11-2025, Pickup Order, Saturday, UTRECHT-STECK | L62: Utrecht Steck - BB met kluit (incl. €10 borg) - Ophalen eerste week - 125-150 cm | M62: 1 | N62: utrecht-steck-bb-met-kluit-incl-10-borg-w1 | O62: Utrecht Steck - BB met kluit (incl. €10 borg) - Ophalen eerste week | P62: fulfilled | Q62: Line Item | R62: 32812691390787 | S62: fulfilled | V62: MET-125-150
A63: UTRECHT-STECK-BOOM-MET-BORG-175-200 | B63: Pickup-Location-Id: 302654 Pickup-Day: sunday Pickup-Date: 2025/12/07 Pickup-Location-Company: UTRECHT - Steck Pickup-Location-Address-Line-1: Gageldijk 3 Pickup-Location-City: Utrecht Pickup-Location-Postal-Code: 3566 ME Pickup-Location-Country: Netherlands Checkout-Method: pickup Pickup-Time: | C63: sunday | D63: 45998 | F63: UTRECHT - Steck | G63: #BB-25-6872 | H63: UTRECHT-STECK-BOOM-MET-BORG-175-200 | I63: 10395093729603 | J63: 07-12-2025, Pickup Order, Sunday, UTRECHT-STECK | L63: Utrecht Steck - BB met kluit (incl. €10 borg) - 175-200 cm | M63: 1 | N63: ut-vandestreek-boom-met-borg | O63: Utrecht Steck - BB met kluit (incl. €10 borg) | Q63: Line Item | R63: 32601734152515 | V63: MET-175-200
A64: EDE-KANTINE-GEBOUW-ENKA-BOOM-MET-BORG-125-150 | B64: Pickup-Location-Id: 278861 Pickup-Day: saturday Pickup-Date: 2025/12/06 Pickup-Time: 10\:30 AM Pickup-Location-Company: EDE - Kantine gebouw Enka Pickup-Location-Address-Line-1: Kantinegebouw 14 Pickup-Location-City: Ede Pickup-Location-Postal-Code: 6717 XR Pickup-Location-Country: Netherlands Checkout-Method: pickup | C64: saturday | D64: 45997 | E64: 10\:30 AM | F64: EDE - Kantine gebouw Enka | G64: #BB-25-6870 | H64: EDE-KANTINE-GEBOUW-ENKA-BOOM-MET-BORG-125-150 | I64: 10394608206147 | J64: 07-12-2025, 11:15, EDE_ENKA, Pickup Order, Sunday | L64: Ede De Kantine Enka - BB met kluit (incl. €10 borg) - 125-150 cm | M64: 1 | N64: ed-de-kantine-enka-boom-met-borg | O64: Ede De Kantine Enka - BB met kluit (incl. €10 borg) | Q64: Line Item | R64: 32600758452547 | V64: MET-125-150
A65: UTRECHT-STECK-BOOM-MET-BORG-150-175 | B65: Pickup-Location-Id: 302654 Pickup-Day: sunday Pickup-Date: 2025/12/07 Pickup-Location-Company: UTRECHT - Steck Pickup-Location-Address-Line-1: Gageldijk 3 Pickup-Location-City: Utrecht Pickup-Location-Postal-Code: 3566 ME Pickup-Location-Country: Netherlands Checkout-Method: pickup Pickup-Time: | C65: sunday | D65: 45998 | F65: UTRECHT - Steck | G65: #BB-25-6875 | H65: UTRECHT-STECK-BOOM-MET-BORG-150-175 | I65: 10395440939331 | J65: 07-12-2025, Pickup Order, Sunday, UTRECHT-STECK | L65: Utrecht Steck - BB met kluit (incl. €10 borg) - 150-175 cm | M65: 1 | N65: ut-vandestreek-boom-met-borg | O65: Utrecht Steck - BB met kluit (incl. €10 borg) | Q65: Line Item | R65: 32602426900803 | V65: MET-150-175
A66: UTRECHT-STECK-BOOM-MET-BORG-125-150 | B66: Pickup-Location-Id: 302654 Pickup-Day: sunday Pickup-Date: 2025/12/07 Pickup-Location-Company: UTRECHT - Steck Pickup-Location-Address-Line-1: Gageldijk 3 Pickup-Location-City: Utrecht Pickup-Location-Postal-Code: 3566 ME Pickup-Location-Country: Netherlands Checkout-Method: pickup Pickup-Time: | C66: sunday | D66: 45998 | F66: UTRECHT - Steck | G66: #BB-25-6876 | H66: UTRECHT-STECK-BOOM-MET-BORG-125-150 | I66: 10395601469763 | J66: 07-12-2025, Pickup Order, Sunday, UTRECHT-STECK | L66: Utrecht Steck - BB met kluit (incl. €10 borg) - 125-150 cm | M66: 1 | N66: ut-vandestreek-boom-met-borg | O66: Utrecht Steck - BB met kluit (incl. €10 borg) | Q66: Line Item | R66: 32602771390787 | V66: MET-125-150
A67: UTRECHT-STECK-BOOM-MET-BORG-125-150 | B67: Pickup-Location-Id: 302654 Pickup-Day: wednesday Pickup-Date: 2025/12/03 Pickup-Location-Company: UTRECHT - Steck Pickup-Location-Address-Line-1: Gageldijk 3 Pickup-Location-City: Utrecht Pickup-Location-Postal-Code: 3566 ME Pickup-Location-Country: Netherlands Checkout-Method: pickup Pickup-Time: | C67: wednesday | D67: 45994 | F67: UTRECHT - Steck | G67: #BB-25-6874 | H67: UTRECHT-STECK-BOOM-MET-BORG-125-150 | I67: 10395227849027 | J67: 03-12-2025, Pickup Order, UTRECHT-STECK, Wednesday | L67: Utrecht Steck - BB met kluit (incl. €10 borg) - 125-150 cm | M67: 1 | N67: ut-vandestreek-boom-met-borg | O67: Utrecht Steck - BB met kluit (incl. €10 borg) | Q67: Line Item | R67: 32601969295683 | V67: MET-125-150
A68: UTRECHT-STECK-BOOM-MET-BORG-125-150 | B68: Pickup-Location-Id: 302654 Pickup-Day: sunday Pickup-Date: 2025/11/30 Pickup-Location-Company: UTRECHT - Steck Pickup-Location-Address-Line-1: Gageldijk 3 Pickup-Location-City: Utrecht Pickup-Location-Postal-Code: 3566 ME Pickup-Location-Country: Netherlands Checkout-Method: pickup Pickup-Time: | C68: sunday | D68: 45991 | F68: UTRECHT - Steck | G68: #BB-25-6882 | H68: UTRECHT-STECK-BOOM-MET-BORG-125-150 | I68: 10398329897283 | J68: 30-11-2025, Pickup Order, Sunday, UTRECHT-STECK | L68: Utrecht Steck - BB met kluit (incl. €10 borg) - 125-150 cm | M68: 1 | N68: ut-vandestreek-boom-met-borg | O68: Utrecht Steck - BB met kluit (incl. €10 borg) | Q68: Line Item | R68: 32608194232643 | V68: MET-125-150
A69: UTRECHT-STECK-BOOM-MET-BORG-100-125 | B69: Pickup-Location-Id: 302654 Pickup-Day: monday Pickup-Date: 2025/12/01 Pickup-Location-Company: UTRECHT - Steck Pickup-Location-Address-Line-1: Gageldijk 3 Pickup-Location-City: Utrecht Pickup-Location-Postal-Code: 3566 ME Pickup-Location-Country: Netherlands Checkout-Method: pickup Pickup-Time: | C69: monday | D69: 45992 | F69: UTRECHT - Steck | G69: #BB-25-6879 | H69: UTRECHT-STECK-BOOM-MET-BORG-100-125 | I69: 10396438069571 | J69: 01-12-2025, Monday, Pickup Order, UTRECHT-STECK | L69: Utrecht Steck - BB met kluit (incl. €10 borg) - 100-125 cm | M69: 1 | N69: ut-vandestreek-boom-met-borg | O69: Utrecht Steck - BB met kluit (incl. €10 borg) | Q69: Line Item | R69: 32604442558787 | V69: MET-100-125
A70: UTRECHT-STECK-BOOM-MET-BORG-100-125 | B70: Pickup-Location-Id: 302654 Pickup-Day: saturday Pickup-Date: 2025/12/06 Pickup-Location-Company: UTRECHT - Steck Pickup-Location-Address-Line-1: Gageldijk 3 Pickup-Location-City: Utrecht Pickup-Location-Postal-Code: 3566 ME Pickup-Location-Country: Netherlands Checkout-Method: pickup Pickup-Time: | C70: saturday | D70: 45997 | F70: UTRECHT - Steck | G70: #BB-25-6877 | H70: UTRECHT-STECK-BOOM-MET-BORG-100-125 | I70: 10395633910083 | J70: 06-12-2025, Pickup Order, Saturday, UTRECHT-STECK | L70: Utrecht Steck - BB met kluit (incl. €10 borg) - 100-125 cm | M70: 1 | N70: ut-vandestreek-boom-met-borg | O70: Utrecht Steck - BB met kluit (incl. €10 borg) | Q70: Line Item | R70: 32602837385539 | V70: MET-100-125
A71: BREDA-KINDERBOERDERIJ-WOLFSLAAR-BOOM-MET-BORG-125-150 | B71: Pickup-Location-Id: 278023 Pickup-Day: saturday Pickup-Date: 2025/12/06 Pickup-Time: 1\:40 PM Pickup-Location-Company: BREDA - Kinderboerderij Wolfslaar Pickup-Location-Address-Line-1: Wolfslaardreef 95 Pickup-Location-City: Breda Pickup-Location-Postal-Code: 4834 SN Pickup-Location-Country: Netherlands Checkout-Method: pickup | C71: saturday | D71: 45997 | E71: 1\:40 PM | F71: BREDA - Kinderboerderij Wolfslaar | G71: #BB-25-6880 | H71: BREDA-KINDERBOERDERIJ-WOLFSLAAR-BOOM-MET-BORG-125-150 | I71: 10397676044611 | J71: 06-12-2025, 13:40, BREDA-WOLFSLAAR, Pickup Order, Saturday | L71: Breda Wolfslaar - BB met kluit (incl. €10 borg) - 125-150 cm | M71: 1 | N71: bda-wolfslaar-boom-met-borg | O71: Breda Wolfslaar - BB met kluit (incl. €10 borg) | Q71: Line Item | R71: 32606887313731 | V71: MET-125-150
A72: DEN-HAAG-PLUK-BOOM-ZONDER-150-175 | B72: Pickup-Location-Id: 278026 Pickup-Day: saturday Pickup-Date: 2025/12/06 Pickup-Time: 11\:00 AM Pickup-Location-Company: DEN HAAG - Pluk! Pickup-Location-Address-Line-1: Loosduinse Hoofdstraat Pickup-Location-City: Den Haag Pickup-Location-Postal-Code: 2552 AV Pickup-Location-Country: Netherlands Pickup-Location-Phone: 0653459881 Checkout-Method: pickup | C72: saturday | D72: 45997 | E72: 11\:00 AM | F72: DEN HAAG - Pluk! | G72: #BB-25-6883 | H72: DEN-HAAG-PLUK-BOOM-ZONDER-150-175 | I72: 10398567334211 | J72: 06-12-2025, 11:00, DENHAAG-PLUK, Pickup Order, Saturday | L72: Den Haag Pluk - BB zonder kluit - 150-175 cm | M72: 1 | N72: dh-pluk-boom-zonder | O72: Den Haag Pluk - BB zonder kluit | Q72: Line Item | R72: 32608668320067 | V72: ZONDER-150-175
A73: BREDA-FRONTAAL-BOOM-MET-BORG-125-150 | B73: Pickup-Location-Id: 279894 Pickup-Day: saturday Pickup-Date: 2025/12/06 Pickup-Time: 2\:00 PM Pickup-Location-Company: BREDA - Frontaal Pickup-Location-Address-Line-1: Liniestraat 31 Pickup-Location-City: Breda Pickup-Location-Postal-Code: 4816 BG Pickup-Location-Country: Netherlands Checkout-Method: pickup | C73: saturday | D73: 45997 | E73: 2\:00 PM | F73: BREDA - Frontaal | G73: #BB-25-6887 | H73: BREDA-FRONTAAL-BOOM-MET-BORG-125-150 | I73: 10399329321283 | J73: 06-12-2025, 14:00, BREDA-FRONTAAL, Pickup Order, Saturday | L73: Breda Frontaal - BB met kluit (incl. €10 borg) - 125-150 | M73: 1 | N73: bda-frontaal-boom-met-borg | O73: Breda Frontaal - BB met kluit (incl. €10 borg) | Q73: Line Item | R73: 32610255864131 | V73: MET-125-150
A74: UTRECHT-STECK-BOOM-MET-BORG-100-125 | B74: Pickup-Location-Id: 302654 Pickup-Day: monday Pickup-Date: 2025/12/01 Pickup-Location-Company: UTRECHT - Steck Pickup-Location-Address-Line-1: Gageldijk 3 Pickup-Location-City: Utrecht Pickup-Location-Postal-Code: 3566 ME Pickup-Location-Country: Netherlands Checkout-Method: pickup Pickup-Time: | C74: monday | D74: 45992 | F74: UTRECHT - Steck | G74: #BB-25-6891 | H74: UTRECHT-STECK-BOOM-MET-BORG-100-125 | I74: 10400208257347 | J74: 01-12-2025, Monday, Pickup Order, UTRECHT-STECK, WAKE-UP | L74: Utrecht Steck - BB met kluit (incl. €10 borg) - 100-125 cm | M74: 1 | N74: ut-vandestreek-boom-met-borg | O74: Utrecht Steck - BB met kluit (incl. €10 borg) | Q74: Line Item | R74: 32612063314243 | V74: MET-100-125
...

Sheet UTRECHT - Namelijst
A1: Name | B1: Billing: First Name | C1: Billing: Last Name | D1: Line: SKU | E1: Line: Quantity | G1: Pickup-Day | H1: Pickup-Date | I1: Pickup-Time | J1: Pickup-Location-Company | K1: Line: Name | L1: Customer: Email | M1: Boomtype
A2: #BB-25-6872 | B2: Inge | C2: van Houdt | D2: UTRECHT-STECK-BOOM-MET-BORG-175-200 | E2: 1 | G2: sunday | H2: 45998 | J2: UTRECHT - Steck | K2: Utrecht Steck - BB met kluit (incl. €10 borg) - 175-200 cm | L2: isvhoudt@gmail.com | M2: MET-175-200
A3: #BB-25-6870 | B3: Marieke | C3: Zwaanswijk | D3: EDE-KANTINE-GEBOUW-ENKA-BOOM-MET-BORG-125-150 | E3: 1 | G3: saturday | H3: 45997 | I3: 10\:30 AM | J3: EDE - Kantine gebouw Enka | K3: Ede De Kantine Enka - BB met kluit (incl. €10 borg) - 125-150 cm | L3: marieke.zwaanswijk@hotmail.com | M3: MET-125-150
A4: #BB-25-6876 | B4: Annet | C4: Troelstra | D4: UTRECHT-STECK-BOOM-MET-BORG-125-150 | E4: 1 | G4: sunday | H4: 45998 | J4: UTRECHT - Steck | K4: Utrecht Steck - BB met kluit (incl. €10 borg) - 125-150 cm | L4: a.troelstra@me.com | M4: MET-125-150
A5: #BB-25-6875 | B5: Geertjan | C5: Aleven | D5: UTRECHT-STECK-BOOM-MET-BORG-150-175 | E5: 1 | G5: sunday | H5: 45998 | J5: UTRECHT - Steck | K5: Utrecht Steck - BB met kluit (incl. €10 borg) - 150-175 cm | L5: geertjan@hartenhoofd.nl | M5: MET-150-175
A6: #BB-25-6879 | B6: Marielle | C6: Spronck | D6: UTRECHT-STECK-BOOM-MET-BORG-100-125 | E6: 1 | G6: monday | H6: 45992 | J6: UTRECHT - Steck | K6: Utrecht Steck - BB met kluit (incl. €10 borg) - 100-125 cm | L6: mariellespronck@gmail.com | M6: MET-100-125
A7: #BB-25-6882 | B7: Bram | C7: Coolen | D7: UTRECHT-STECK-BOOM-MET-BORG-125-150 | E7: 1 | G7: sunday | H7: 45991 | J7: UTRECHT - Steck | K7: Utrecht Steck - BB met kluit (incl. €10 borg) - 125-150 cm | L7: bramcoolen1982@gmail.com | M7: MET-125-150
A8: #BB-25-6877 | B8: Hermine | C8: Reuchlin | D8: UTRECHT-STECK-BOOM-MET-BORG-100-125 | E8: 1 | G8: saturday | H8: 45997 | J8: UTRECHT - Steck | K8: Utrecht Steck - BB met kluit (incl. €10 borg) - 100-125 cm | L8: info@herminereuchlin.nl | M8: MET-100-125
A9: #BB-25-6874 | B9: Bregje | C9: van den Berg | D9: UTRECHT-STECK-BOOM-MET-BORG-125-150 | E9: 1 | G9: wednesday | H9: 45994 | J9: UTRECHT - Steck | K9: Utrecht Steck - BB met kluit (incl. €10 borg) - 125-150 cm | L9: bregje0310@gmail.com | M9: MET-125-150
A10: #BB-25-6886 | B10: Marike | C10: STRASHEIM | D10: UTRECHT-STECK-BOOM-MET-BORG-150-175 | E10: 1 | G10: saturday | H10: 45990 | J10: UTRECHT - Steck | K10: Utrecht Steck - BB met kluit (incl. €10 borg) - 150-175 cm | L10: marike.strasheim@gmail.com | M10: MET-150-175
A11: #BB-25-6880 | B11: Renate | C11: de Jaeger | D11: BREDA-KINDERBOERDERIJ-WOLFSLAAR-BOOM-MET-BORG-125-150 | E11: 1 | G11: saturday | H11: 45997 | I11: 1\:40 PM | J11: BREDA - Kinderboerderij Wolfslaar | K11: Breda Wolfslaar - BB met kluit (incl. €10 borg) - 125-150 cm | L11: rm.de.jaeger@ziggo.nl | M11: MET-125-150
A12: #BB-25-6884 | B12: Simone | C12: van Eik | D12: AMSTERDAM-HOUSE-OF-WATT-BOOM-MET-BORG-125-150 | E12: 1 | G12: sunday | H12: 45991 | I12: 1\:00 PM | J12: AMSTERDAM - Molen De Otter | K12: Amsterdam Molen de Otter - BB met kluit (incl. €10 borg) - 125-150 cm | L12: vaneiks@gmail.com | M12: MET-125-150
A13: #BB-25-6887 | B13: Misja | C13: de Bruijn | D13: BREDA-FRONTAAL-BOOM-MET-BORG-125-150 | E13: 1 | G13: saturday | H13: 45997 | I13: 2\:00 PM | J13: BREDA - Frontaal | K13: Breda Frontaal - BB met kluit (incl. €10 borg) - 125-150 | L13: debruijnmisja@gmail.com | M13: MET-125-150
A14: #BB-25-6891 | B14: Margot | C14: Huijgen | D14: UTRECHT-STECK-BOOM-MET-BORG-100-125 | E14: 1 | G14: monday | H14: 45992 | J14: UTRECHT - Steck | K14: Utrecht Steck - BB met kluit (incl. €10 borg) - 100-125 cm | L14: margothuijgen@gmail.com | M14: MET-100-125
A15: #BB-25-6883 | B15: Dirk | C15: R. | D15: DEN-HAAG-PLUK-BOOM-ZONDER-150-175 | E15: 1 | G15: saturday | H15: 45997 | I15: 11\:00 AM | J15: DEN HAAG - Pluk! | K15: Den Haag Pluk - BB zonder kluit - 150-175 cm | L15: dirkjan.rijneveld@gmail.com | M15: ZONDER-150-175
A16: #BB-25-6894 | B16: Metta | C16: Pratt | D16: UTRECHT-STECK-BOOM-MET-BORG-150-175 | E16: 1 | G16: thursday | H16: 45995 | J16: UTRECHT - Steck | K16: Utrecht Steck - BB met kluit (incl. €10 borg) - 150-175 cm | L16: mettapratt@gmail.com | M16: MET-150-175
A17: #BB-25-6889 | B17: Chiara | C17: Treglia | D17: EINDHOVEN-WASVEN-BOOM-MET-BORG-125-150 | E17: 1 | G17: saturday | H17: 45997 | I17: 10\:15 AM | J17: EINDHOVEN - Wasven | K17: Eindhoven Wasven - BB met kluit (incl. €10 borg) - 125-150 cm | L17: info@chiaratreglia.com | M17: MET-125-150
A18: #BB-25-6890 | B18: Tiffany | C18: Tjong | D18: AMSTERDAM-KOPVANOOST-BOOM-MET-BORG-125-150 | E18: 1 | G18: sunday | H18: 45998 | I18: 2\:00 PM | J18: AMSTERDAM - Kop van Oost | K18: Amsterdam Kop van Oost - BB met kluit (incl. €10 borg) - 125-150 cm | L18: tiffany.tjong@gmail.com | M18: MET-125-150
A19: #BB-25-6898 | B19: Richard | C19: Duplock | D19: UTRECHT-STECK-BOOM-MET-BORG-125-150 | E19: 1 | G19: saturday | H19: 45997 | J19: UTRECHT - Steck | K19: Utrecht Steck - BB met kluit (incl. €10 borg) - 125-150 cm | L19: richard.duplock@outlook.com | M19: MET-125-150
A20: #BB-25-6893 | B20: Roos | C20: Kool | D20: EDE-KANTINE-GEBOUW-ENKA-BOOM-ZONDER-175-200 | E20: 1 | G20: saturday | H20: 45997 | I20: 10\:30 AM | J20: EDE - Kantine gebouw Enka | K20: Ede De Kantine Enka - BB zonder kluit - 175-200 cm | L20: hanneroosbouwman@gmail.com | M20: ZONDER-175-200
A21: #BB-25-6900 | B21: Arjan | C21: van Asselt | D21: EDE-KANTINE-GEBOUW-ENKA-BOOM-MET-BORG-100-125 | E21: 1 | G21: saturday | H21: 45997 | I21: 12\:15 PM | J21: EDE - Kantine gebouw Enka | K21: Ede De Kantine Enka - BB met kluit (incl. €10 borg) - 100-125 cm | L21: arjan.vanasselt@gmail.com | M21: MET-100-125
A22: #BB-25-6895 | B22: U | C22: Schiller | D22: LEIDEN-PLNT-BOOM-MET-BORG-100-125 | E22: 1 | G22: sunday | H22: 45991 | I22: 12\:00 PM | J22: LEIDEN - The Fields | K22: Leiden the field - BB met kluit (incl. €10 borg) - 100-125 cm | L22: myriam.schiller@gmail.com | M22: MET-100-125
A23: #BB-25-6897 | B23: Emma | C23: Smit | D23: AMSTERDAM-VONDELTUIN-BOOM-MET-125-150 | E23: 1 | G23: saturday | H23: 45997 | I23: 12\:00 PM | J23: AMSTERDAM - Vondeltuin | K23: Amsterdam Vondeltuin - BB met kluit (incl. €10 borg) - 125-150 cm | L23: xemmasmit@hotmail.com | M23: MET-125-150
A24: #BB-25-6904 | B24: Kari | C24: Jasperse | D24: UTRECHT-STECK-BOOM-MET-BORG-125-150 | E24: 1 | G24: thursday | H24: 45995 | J24: UTRECHT - Steck | K24: Utrecht Steck - BB met kluit (incl. €10 borg) - 125-150 cm | L24: karivita02@hotmail.com | M24: MET-125-150
A25: #BB-25-6899 | B25: Odilia | C25: Laceulle | D25: UTRECHT-STECK-BOOM-ZONDER-150-175 | E25: 1 | G25: sunday | H25: 45997 | J25: UTRECHT - Steck | K25: Utrecht Steck - BB zonder kluit - 150-175 cm | L25: odilialac@hotmail.com | M25: ZONDER-150-175
A26: #BB-25-6906 | B26: Febe | C26: van Maldegem | D26: UTRECHT-STECK-BOOM-MET-BORG-175-200 | E26: 1 | G26: saturday | H26: 45990 | J26: UTRECHT - Steck | K26: Utrecht Steck - BB met kluit (incl. €10 borg) - 175-200 cm | L26: beterboompje@email.febe.nl | M26: MET-175-200
A27: #BB-25-6903 | B27: Daniël | C27: Reinders | D27: GOUDA-STADSKANT-BOOM-MET-BORG-125-150 | E27: 1 | G27: saturday | H27: 45997 | I27: 10\:15 AM | J27: GOUDA - Stadskant | K27: Gouda Stadskant - BB met kluit (incl. €10 borg) - 125-150 cm | L27: daniel@danielreinders.nl | M27: MET-125-150
A28: #BB-25-6902 | B28: Rosalie | C28: Snijders | D28: DEN-HAAG-PLUK-BOOM-MET-BORG-125-150 | E28: 1 | G28: saturday | H28: 45997 | I28: 12\:00 PM | J28: DEN HAAG - Pluk! | K28: Den Haag Pluk - BB met kluit (incl. €10 borg) - 125-150 cm | L28: snijdersrosalie@hotmail.com | M28: MET-125-150
A29: #BB-25-6910 | B29: Renske | C29: Stel | D29: UTRECHT-STECK-BOOM-MET-BORG-125-150 | E29: 1 | G29: saturday | H29: 45997 | J29: UTRECHT - Steck | K29: Utrecht Steck - BB met kluit (incl. €10 borg) - 125-150 cm | L29: renskepompe@hotmail.com | M29: MET-125-150
A30: #BB-25-6913 | B30: C. | C30: Snoeij | D30: GOUDA-STADSKANT-BOOM-MET-BORG-125-150 | E30: 1 | G30: sunday | H30: 45998 | I30: 12\:45 PM | J30: GOUDA - Stadskant | K30: Gouda Stadskant - BB met kluit (incl. €10 borg) - 125-150 cm | L30: cornesnoeij@soverin.net | M30: MET-125-150
A31: #BB-25-6905 | B31: Marie-Louise | C31: Beuming | D31: AMSTERDAM-VONDELTUIN-BOOM-ZONDER-175-200 | E31: 1 | G31: saturday | H31: 45997 | I31: 10\:00 AM | J31: AMSTERDAM - Vondeltuin | K31: Amsterdam Vondeltuin - BB zonder kluit - 175-200 cm | L31: mbeuming@xs4all.nl | M31: ZONDER-175-200
A32: #BB-25-6915 | B32: Marja | C32: Heier | D32: UTRECHT-STECK-BOOM-MET-BORG-100-125 | E32: 1 | G32: wednesday | H32: 45994 | J32: UTRECHT - Steck | K32: Utrecht Steck - BB met kluit (incl. €10 borg) - 100-125 cm | L32: mrjheier@gmail.com | M32: MET-100-125
A33: #BB-25-6907 | B33: Sabien | C33: Gerretse | D33: BREDA-FRONTAAL-BOOM-ZONDER-175-200 | E33: 1 | G33: saturday | H33: 45997 | I33: 2\:00 PM | J33: BREDA - Frontaal | K33: Breda Frontaal - BB zonder kluit - 175-200 | L33: sgerretse@outlook.com | M33: ZONDER-175-200
A34: #BB-25-6917 | B34: addy | C34: zwiebel | D34: UTRECHT-STECK-BOOM-MET-BORG-125-150 | E34: 1 | G34: saturday | H34: 45990 | J34: UTRECHT - Steck | K34: Utrecht Steck - BB met kluit (incl. €10 borg) - 125-150 cm | L34: aprzwiebel@gmail.com | M34: MET-125-150
A35: #BB-25-6918 | B35: Puck | C35: Metgod | D35: AMSTERDAM-VONDELTUIN-BOOM-MET-150-175 | E35: 1 | G35: saturday | H35: 45997 | I35: 11\:00 AM | J35: AMSTERDAM - Vondeltuin | K35: Amsterdam Vondeltuin - BB met kluit (incl. €10 borg) - 150-175 cm | L35: puckmetgod@gmail.com | M35: MET-150-175
A36: #BB-25-6919 | B36: Elysa | C36: Overdijk | D36: EDE-KANTINE-GEBOUW-ENKA-BOOM-MET-BORG-125-150 | E36: 1 | G36: saturday | H36: 45997 | I36: 10\:00 AM | J36: EDE - Kantine gebouw Enka | K36: Ede De Kantine Enka - BB met kluit (incl. €10 borg) - 125-150 cm | L36: elysaoverdijk@gmail.com | M36: MET-125-150
A37: #BB-25-6920 | B37: Jochem | C37: Kuijs | D37: AMSTERDAM-KOPVANOOST-BOOM-MET-BORG-175-200 | E37: 1 | G37: sunday | H37: 45998 | I37: 11\:00 AM | J37: AMSTERDAM - Kop van Oost | K37: Amsterdam Kop van Oost - BB met kluit (incl. €10 borg) - 175-200 cm | L37: jochemkuijs@hotmail.com | M37: MET-175-200
A38: #BB-25-6921 | B38: Dik | C38: Habbema | D38: UTRECHT-STECK-BOOM-MET-BORG-125-150 | E38: 1 | G38: friday | H38: 45996 | J38: UTRECHT - Steck | K38: Utrecht Steck - BB met kluit (incl. €10 borg) - 125-150 cm | L38: dikhabbema@hotmail.com | M38: MET-125-150
A39: #BB-25-6922 | B39: Mitchel | C39: Bakker | D39: AMSTERDAM-VONDELTUIN-BOOM-MET-150-175 | E39: 1 | G39: saturday | H39: 46004 | I39: 11\:30 AM | J39: AMSTERDAM - Vondeltuin | K39: Amsterdam Vondeltuin - BB met kluit (incl. €10 borg) - 150-175 cm | L39: mitchel1993@gmail.com | M39: MET-150-175
A40: #BB-25-6923 | B40: Sabien | C40: Froger | D40: BREDA-KINDERBOERDERIJ-WOLFSLAAR-BOOM-MET-BORG-125-150 | E40: 1 | G40: sunday | H40: 45998 | I40: 11\:00 AM | J40: BREDA - Kinderboerderij Wolfslaar | K40: Breda Wolfslaar - BB met kluit (incl. €10 borg) - 125-150 cm | L40: sabienfr@hotmail.com | M40: MET-125-150
...

Sheet GOUDA - Namelijst
A1: Name | B1: Billing: First Name | C1: Billing: Last Name | D1: Line: SKU | E1: Line: Quantity | F1: Pickup-Day | G1: Pickup-Date | H1: Pickup-Time | I1: Boomtype
A2: #BB-25-7024 | B2: Audrey | C2: Ledanois | D2: GOUDA-STADSKANT-BOOM-MET-BORG-100-125 | E2: 1 | F2: saturday | G2: 45990 | H2: 3\:45 PM | I2: MET-100-125
A3: #BB-25-7005 | B3: Sarah | C3: Evers | D3: GOUDA-STADSKANT-BOOM-MET-BORG-100-125 | E3: 1 | F3: saturday | G3: 45990 | H3: 12\:45 PM | I3: MET-100-125
A4: #BB-25-7808 | B4: Jan Maarten | C4: Gaasbeek | D4: GOUDA-STADSKANT-BOOM-MET-BORG-125-150 | E4: 1 | F4: saturday | G4: 45990 | H4: 2\:15 PM | I4: MET-125-150
A5: #BB-25-7785 | B5: Monique | C5: Pluim | D5: GOUDA-STADSKANT-BOOM-ZONDER-175-200 | E5: 1 | F5: saturday | G5: 45990 | H5: 2\:45 PM | I5: ZONDER-175-200
A6: #BB-25-7934 | B6: Mirjam | C6: de Geus | D6: GOUDA-STADSKANT-BOOM-MET-BORG-125-150 | E6: 1 | F6: saturday | G6: 45990 | H6: 11\:15 AM | I6: MET-125-150
A7: #BB-25-8139 | B7: Yvo | C7: Steenbergen | D7: GOUDA-STADSKANT-BOOM-MET-BORG-175-200 | E7: 1 | F7: saturday | G7: 45990 | H7: 10\:15 AM | I7: MET-175-200
A8: #BB-25-8226 | B8: Evelien | C8: Smits | D8: GOUDA-STADSKANT-BOOM-ZONDER-175-200 | E8: 1 | F8: saturday | G8: 45990 | H8: 12\:45 PM | I8: ZONDER-175-200
A9: #BB-25-8270 | B9: Janneke | C9: Veldhuis | D9: GOUDA-STADSKANT-BOOM-MET-BORG-150-175 | E9: 1 | F9: saturday | G9: 45990 | H9: 12\:15 PM | I9: MET-150-175
A10: #BB-25-8408 | B10: Noor | C10: Heerkens | D10: GOUDA-STADSKANT-BOOM-MET-BORG-125-150 | E10: 1 | F10: saturday | G10: 45990 | H10: 2\:45 PM | I10: MET-125-150
A11: #BB-25-8466 | B11: Maja | C11: van der Voet | D11: GOUDA-STADSKANT-BOOM-MET-BORG-150-175 | E11: 1 | F11: saturday | G11: 45990 | H11: 1\:15 PM | I11: MET-150-175
A12: #BB-25-8622 | B12: Linda | C12: van der Schaaf | D12: GOUDA-STADSKANT-BOOM-MET-BORG-125-150 | E12: 1 | F12: saturday | G12: 45990 | H12: 10\:45 AM | I12: MET-125-150
A13: #BB-25-8717 | B13: Liana | C13: Barenbrug | D13: GOUDA-STADSKANT-BOOM-MET-BORG-125-150 | E13: 1 | F13: saturday | G13: 45990 | H13: 10\:15 AM | I13: MET-125-150
... A25: #BB-25-8639 | B25: Dorotheé | C25: Beens - Nieuwveld | D25: GOUDA-STADSKANT-BOOM-MET-BORG-125-150 | E25: 1 | F25: sunday | G25: 45991 | H25: 12\:15 PM | I25: MET-125-150

Sheet Molen de otter | Namelijst
A1: Billing: First Name | B1: Billing: Last Name | C1: Line: SKU | D1: Line: Quantity | E1: Pickup-Day | F1: Pickup-Date | G1: Pickup-Time | H1: Pickup-Location-Company
A2: Nicola | B2: Arencibia Roca | C2: AMSTERDAM-MOLEN-DE-OTTER-BOOM-ZONDER-175-200 | D2: 1 | E2: sunday | F2: 45991 | G2: 11\:30 AM | H2: AMSTERDAM - Molen De Otter
A3: Rosa | B3: Asbreuk | C3: AMSTERDAM-MOLEN-DE-OTTER-BOOM-ZONDER-150-175 | D3: 1 | E3: sunday | F3: 45991 | G3: 3\:30 PM | H3: AMSTERDAM - Molen De Otter
A4: Ioana | B4: Biris | C4: AMSTERDAM-MOLEN-DE-OTTER-BOOM-ZONDER-250-300 | D4: 1 | E4: sunday | F4: 45991 | G4: 11\:00 AM | H4: AMSTERDAM - Molen De Otter
A5: Dana | B5: Blekkenhorst | C5: AMSTERDAM-HOUSE-OF-WATT-BOOM-MET-BORG-125-150 | D5: 1 | E5: sunday | F5: 45991 | G5: 12\:30 PM | H5: AMSTERDAM - Molen De Otter
A6: Laura | B6: Bolczek | C6: AMSTERDAM-MOLEN-DE-OTTER-BOOM-ZONDER-150-175 | D6: 1 | E6: sunday | F6: 45991 | G6: 12\:00 PM | H6: AMSTERDAM - Molen De Otter
A7: Corinne | B7: Bolink | C7: AMSTERDAM-HOUSE-OF-WATT-BOOM-MET-BORG-125-150 | D7: 1 | E7: sunday | F7: 45991 | G7: 11\:00 AM | H7: AMSTERDAM - Molen De Otter
A8: Marten | B8: Bolt | C8: AMSTERDAM-HOUSE-OF-WATT-BOOM-MET-BORG-125-150 | D8: 1 | E8: sunday | F8: 45991 | G8: 10\:00 AM | H8: AMSTERDAM - Molen De Otter
A9: Marieke | B9: Brentjens | C9: AMSTERDAM-HOUSE-OF-WATT-BOOM-MET-BORG-175-200 | D9: 1 | E9: sunday | F9: 45991 | G9: 11\:00 AM | H9: AMSTERDAM - Molen De Otter
A10: Bente | B10: Broers | C10: AMSTERDAM-MOLEN-DE-OTTER-BOOM-ZONDER-175-200 | D10: 1 | E10: sunday | F10: 45991 | G10: 10\:00 AM | H10: AMSTERDAM - Molen De Otter
A11: Alex | B11: Covizzi | C11: AMSTERDAM-HOUSE-OF-WATT-BOOM-MET-BORG-100-125 | D11: 1 | E11: sunday | F11: 45991 | G11: 1\:30 PM | H11: AMSTERDAM - Molen De Otter
A12: Kenza | B12: Cruden | C12: AMSTERDAM-MOLEN-DE-OTTER-BOOM-ZONDER-175-200 | D12: 1 | E12: sunday | F12: 45991 | G12: 1\:30 PM | H12: AMSTERDAM - Molen De Otter
A13: Roswitha | B13: de Joode | C13: AMSTERDAM-HOUSE-OF-WATT-BOOM-MET-BORG-100-125 | D13: 1 | E13: sunday | F13: 45991 | G13: 10\:00 AM | H13: AMSTERDAM - Molen De Otter
... A68: Marieke | B68: Zwagerman | C68: AMSTERDAM-MOLEN-DE-OTTER-BOOM-ZONDER-150-175 | D68: 1 | E68: sunday | F68: 45991 | G68: 11\:30 AM | H68: AMSTERDAM - Molen De Otter

Sheet BB | Input D&K
A1: Line: SKU | B1: Additional Details | C1: Pickup-Day | D1: Pickup-Date | E1: Pickup-Time | F1: Pickup-Location-Company | G1: Line: Quantity | H1: Line: Product Handle | I1: Line: Name | J1: Line: Variant SKU | K1: Tags | L1: Line: Product Type | M1: Line: Title | N1: Line: Fulfillment Status | O1: Line: Type | P1: Line: ID | Q1: Order Fulfillment Status | R1: Note | S1: Customer: First Name | T1: Customer: Last Name | U1: Boomtype
A2: ANTWERPEN-DILLE-KAMILLE-BOOM-MET-BORG-125-150 CM | B2: Pickup-Location-Id: 278025 Pickup-Day: tuesday Pickup-Date: 2025/12/09 Pickup-Time: 5\:30 PM Pickup-Location-Company: ANTWERPEN - Dille & Kamille Pickup-Location-Address-Line-1: Vleminckstraat 9 Pickup-Location-City: Antwerpen Pickup-Location-Postal-Code: 2000 Pickup-Location-Country: Belgium Checkout-Method: pickup | C2: tuesday | D2: 46000 | E2: 5\:30 PM | F2: ANTWERPEN - Dille & Kamille | G2: 1 | H2: ant-dille-kamille-boom-met-borg | I2: Antwerpen Dille & Kamille - BB met kluit (incl. €10 borg) - 125-150 cm | J2: ANTWERPEN-DILLE-KAMILLE-BOOM-MET-BORG-125-150 CM | K2: 09-12-2025, 17:30, ANTWERPEN-DENK, Pickup Order, Tuesday, WAKE-UP | M2: Antwerpen Dille & Kamille - BB met kluit (incl. €10 borg) | O2: Line Item | P2: 32666384138563 | S2: Saskia | T2: Steenmeijer | U2: MET-125-150
A3: ROTTERDAM-DILLE-KAMILLE-BOOM-MET-BORG-125-150 CM | B3: Pickup-Location-Id: 278029 Pickup-Day: monday Pickup-Date: 2025/12/08 Pickup-Time: 2\:00 PM Pickup-Location-Company: ROTTERDAM - Dille & Kamille Pickup-Location-Address-Line-1: Korte Hoogstraat 22 Pickup-Location-City: Rotterdam Pickup-Location-Postal-Code: 3011 GL Pickup-Location-Country: Netherlands Checkout-Method: pickup | C3: monday | D3: 45999 | E3: 2\:00 PM | F3: ROTTERDAM - Dille & Kamille | G3: 1 | H3: rtd-dille-kamille-boom-met-borg | I3: Rotterdam Dille & Kamille - BB met kluit (incl. €10 borg) - 125-150 cm | J3: ROTTERDAM-DILLE-KAMILLE-BOOM-MET-BORG-125-150 CM | K3: 08-12-2025, 14:00, Monday, Pickup Order, ROTTERDAM-DENK, WAKE-UP | M3: Rotterdam Dille & Kamille - BB met kluit (incl. €10 borg) | O3: Line Item | P3: 32670782947651 | S3: Leonoor | T3: den Ottolander | U3: MET-125-150
A4: ANTWERPEN-DILLE-KAMILLE-BOOM-MET-BORG-125-150 CM | B4: Pickup-Location-Id: 278025 Pickup-Day: tuesday Pickup-Date: 2025/12/09 Pickup-Time: 12\:00 PM Pickup-Location-Company: ANTWERPEN - Dille & Kamille Pickup-Location-Address-Line-1: Vleminckstraat 9 Pickup-Location-City: Antwerpen Pickup-Location-Postal-Code: 2000 Pickup-Location-Country: Belgium Checkout-Method: pickup | C4: tuesday | D4: 46000 | E4: 12\:00 PM | F4: ANTWERPEN - Dille & Kamille | G4: 1 | H4: ant-dille-kamille-boom-met-borg | I4: Antwerpen Dille & Kamille - BB met kluit (incl. €10 borg) - 125-150 cm | J4: ANTWERPEN-DILLE-KAMILLE-BOOM-MET-BORG-125-150 CM | K4: 09-12-2025, 12:00, ANTWERPEN-DENK, Pickup Order, Tuesday, WAKE-UP | M4: Antwerpen Dille & Kamille - BB met kluit (incl. €10 borg) | O4: Line Item | P4: 32694400975171 | S4: Dorien | T4: De Vroey | U4: MET-125-150
A5: AMSTERDAM-DILLE-KAMILLE-BOOM-MET-BORG-125-150 CM | B5: Pickup-Location-Id: 278032 Pickup-Day: monday Pickup-Date: 2025/12/01 Pickup-Time: 5\:00 PM Pickup-Location-Company: AMSTERDAM BILDERDIJK - Dille & Kamille Pickup-Location-Address-Line-1: Bilderdijkstraat 187 - 189 Pickup-Location-City: Amsterdam Pickup-Location-Postal-Code: 1053 KR Pickup-Location-Country: Netherlands Checkout-Method: pickup | C5: monday | D5: 45992 | E5: 5\:00 PM | F5: AMSTERDAM BILDERDIJK - Dille & Kamille | G5: 1 | H5: amd-dille-kamille-boom-met-borg | I5: Amsterdam Dille & Kamille - BB met kluit (incl. €10 borg) - 125-150 cm | J5: AMSTERDAM-DILLE-KAMILLE-BOOM-MET-BORG-125-150 CM | K5: 01-12-2025, 17:00, AMSTERDAM, DENK, Monday, Pickup Order, WAKE-UP | M5: Amsterdam Dille & Kamille - BB met kluit (incl. €10 borg) | O5: Line Item | P5: 32692666499395 | S5: Myrte E. | T5: Van Westenbrugge | U5: MET-125-150
A6: ROTTERDAM-DILLE-KAMILLE-BOOM-MET-BORG-125-150 CM | B6: Pickup-Location-Id: 278029 Pickup-Day: wednesday Pickup-Date: 2025/12/10 Pickup-Time: 3\:00 PM Pickup-Location-Company: ROTTERDAM - Dille & Kamille Pickup-Location-Address-Line-1: Korte Hoogstraat 22 Pickup-Location-City: Rotterdam Pickup-Location-Postal-Code: 3011 GL Pickup-Location-Country: Netherlands Checkout-Method: pickup | C6: wednesday | D6: 46001 | E6: 3\:00 PM | F6: ROTTERDAM - Dille & Kamille | G6: 1 | H6: rtd-dille-kamille-boom-met-borg | I6: Rotterdam Dille & Kamille - BB met kluit (incl. €10 borg) - 125-150 cm | J6: ROTTERDAM-DILLE-KAMILLE-BOOM-MET-BORG-125-150 CM | K6: 10-12-2025, 15:00, Pickup Order, ROTTERDAM-DENK, WAKE-UP, Wednesday | M6: Rotterdam Dille & Kamille - BB met kluit (incl. €10 borg) | O6: Line Item | P6: 32684580962627 | S6: Marc | T6: Abbink | U6: MET-125-150
A7: ROTTERDAM-DILLE-KAMILLE-BOOM-MET-BORG-100-125 CM | B7: Pickup-Location-Id: 278029 Pickup-Day: wednesday Pickup-Date: 2025/12/03 Pickup-Time: 3\:00 PM Pickup-Location-Company: ROTTERDAM - Dille & Kamille Pickup-Location-Address-Line-1: Korte Hoogstraat 22 Pickup-Location-City: Rotterdam Pickup-Location-Postal-Code: 3011 GL Pickup-Location-Country: Netherlands Checkout-Method: pickup | C7: wednesday | D7: 45994 | E7: 3\:00 PM | F7: ROTTERDAM - Dille & Kamille | G7: 1 | H7: rtd-dille-kamille-boom-met-borg | I7: Rotterdam Dille & Kamille - BB met kluit (incl. €10 borg) - 100-125 cm | J7: ROTTERDAM-DILLE-KAMILLE-BOOM-MET-BORG-100-125 CM | K7: 03-12-2025, 15:00, Pickup Order, ROTTERDAM-DENK, WAKE-UP, Wednesday | M7: Rotterdam Dille & Kamille - BB met kluit (incl. €10 borg) | O7: Line Item | P7: 32684220219715 | S7: Kaila | T7: Vreeken | U7: MET-100-125
A8: ARNHEM-DILLE-KAMILLE-BOOM-MET-BORG-100-125 CM | B8: Pickup-Location-Id: 278036 Pickup-Day: tuesday Pickup-Date: 2025/12/02 Pickup-Time: 5\:30 PM Pickup-Location-Company: ARNHEM - Dille & Kamille Pickup-Location-Address-Line-1: Bakkerstraat 60 Pickup-Location-City: Arnhem Pickup-Location-Postal-Code: 6811 EJ Pickup-Location-Country: Netherlands Checkout-Method: pickup | C8: tuesday | D8: 45993 | E8: 5\:30 PM | F8: ARNHEM - Dille & Kamille | G8: 1 | H8: arh-dille-kamille-boom-met-borg | I8: Arnhem Dille & Kamille - BB met kluit (incl. €10 borg) - 100-125 cm | J8: ARNHEM-DILLE-KAMILLE-BOOM-MET-BORG-100-125 CM | K8: 02-12-2025, 17:30, ARNHEM-DENK, Pickup Order, Tuesday, WAKE-UP | M8: Arnhem Dille & Kamille - BB met kluit (incl. €10 borg) | O8: Line Item | P8: 32694631661891 | S8: Erwin | T8: Steijnen | U8: MET-100-125
A9: AMSTERDAM-DILLE-KAMILLE-BOOM-MET-BORG-100-125 CM | B9: Pickup-Location-Id: 278032 Pickup-Day: monday Pickup-Date: 2025/12/01 Pickup-Time: 2\:00 PM Pickup-Location-Company: AMSTERDAM BILDERDIJK - Dille & Kamille Pickup-Location-Address-Line-1: Bilderdijkstraat 187 - 189 Pickup-Location-City: Amsterdam Pickup-Location-Postal-Code: 1053 KR Pickup-Location-Country: Netherlands Checkout-Method: pickup | C9: monday | D9: 45992 | E9: 2\:00 PM | F9: AMSTERDAM BILDERDIJK - Dille & Kamille | G9: 1 | H9: amd-dille-kamille-boom-met-borg | I9: Amsterdam Dille & Kamille - BB met kluit (incl. €10 borg) - 100-125 cm | J9: AMSTERDAM-DILLE-KAMILLE-BOOM-MET-BORG-100-125 CM | K9: 01-12-2025, 14:00, AMSTERDAM, DENK, Monday, Pickup Order, WAKE-UP | M9: Amsterdam Dille & Kamille - BB met kluit (incl. €10 borg) | O9: Line Item | P9: 32694838460739 | S9: brigit | T9: hillenius | U9: MET-100-125
A10: ROTTERDAM-DILLE-KAMILLE-BOOM-MET-BORG-125-150 CM | B10: Pickup-Location-Id: 278029 Pickup-Day: monday Pickup-Date: 2025/12/08 Pickup-Time: 4\:30 PM Pickup-Location-Company: ROTTERDAM - Dille & Kamille Pickup-Location-Address-Line-1: Korte Hoogstraat 22 Pickup-Location-City: Rotterdam Pickup-Location-Postal-Code: 3011 GL Pickup-Location-Country: Netherlands Checkout-Method: pickup | C10: monday | D10: 45999 | E10: 4\:30 PM | F10: ROTTERDAM - Dille & Kamille | G10: 1 | H10: rtd-dille-kamille-boom-met-borg | I10: Rotterdam Dille & Kamille - BB met kluit (incl. €10 borg) - 125-150 cm | J10: ROTTERDAM-DILLE-KAMILLE-BOOM-MET-BORG-125-150 CM | K10: 08-12-2025, 16:30, Monday, Pickup Order, ROTTERDAM-DENK, WAKE-UP | M10: Rotterdam Dille & Kamille - BB met kluit (incl. €10 borg) | O10: Line Item | P10: 32696706793795 | S10: René | T10: Van Lier | U10: MET-125-150
A11: DEN-HAAG-DILLE-KAMILLE-BOOM-MET-BORG-100-125 CM | B11: Pickup-Location-Id: 278035 Pickup-Day: monday Pickup-Date: 2025/12/01 Pickup-Time: 12\:00 PM Pickup-Location-Company: DEN HAAG - Dille & Kamille Pickup-Location-Address-Line-1: Noordeinde 44 Pickup-Location-City: Den Haag Pickup-Location-Postal-Code: 2514 GJ Pickup-Location-Country: Netherlands Checkout-Method: pickup | C11: monday | D11: 45992 | E11: 12\:00 PM | F11: DEN HAAG - Dille & Kamille | G11: 1 | H11: dh-dille-kamille-boom-met-borg | I11: Den Haag Dille & Kamille - BB met kluit (incl. €10 borg) - 100-125 cm | J11: DEN-HAAG-DILLE-KAMILLE-BOOM-MET-BORG-100-125 CM | K11: 01-12-2025, 12:00, DENHAAG-DENK, Monday, Pickup Order, WAKE-UP | M11: Den Haag Dille & Kamille - BB met kluit (incl. €10 borg) | O11: Line Item | P11: 32696827773251 | S11: Jitse | T11: de Vriend | U11: MET-100-125
A12: DEN-HAAG-DILLE-KAMILLE-BOOM-MET-BORG-125-150 CM | B12: Pickup-Location-Id: 278035 Pickup-Day: monday Pickup-Date: 2025/12/08 Pickup-Time: 5\:00 PM Pickup-Location-Company: DEN HAAG - Dille & Kamille Pickup-Location-Address-Line-1: Noordeinde 44 Pickup-Location-City: Den Haag Pickup-Location-Postal-Code: 2514 GJ Pickup-Location-Country: Netherlands Checkout-Method: pickup | C12: monday | D12: 45999 | E12: 5\:00 PM | F12: DEN HAAG - Dille & Kamille | G12: 1 | H12: dh-dille-kamille-boom-met-borg | I12: Den Haag Dille & Kamille - BB met kluit (incl. €10 borg) - 125-150 cm | J12: DEN-HAAG-DILLE-KAMILLE-BOOM-MET-BORG-125-150 CM | K12: 08-12-2025, 17:00, DENHAAG-DENK, Monday, Pickup Order, WAKE-UP | M12: Den Haag Dille & Kamille - BB met kluit (incl. €10 borg) | O12: Line Item | P12: 32694761980227 | S12: Fam | T12: Tilanus | U12: MET-125-150
A13: AMSTERDAM-DILLE-KAMILLE-BOOM-MET-BORG-125-150 CM | B13: Pickup-Location-Id: 278032 Pickup-Day: monday Pickup-Date: 2025/12/08 Pickup-Time: 4\:00 PM Pickup-Location-Company: AMSTERDAM BILDERDIJK - Dille & Kamille Pickup-Location-Address-Line-1: Bilderdijkstraat 187 - 189 Pickup-Location-City: Amsterdam Pickup-Location-Postal-Code: 1053 KR Pickup-Location-Country: Netherlands Checkout-Method: pickup | C13: monday | D13: 45999 | E13: 4\:00 PM | F13: AMSTERDAM BILDERDIJK - Dille & Kamille | G13: 1 | H13: amd-dille-kamille-boom-met-borg | I13: Amsterdam Dille & Kamille - BB met kluit (incl. €10 borg) - 125-150 cm | J13: AMSTERDAM-DILLE-KAMILLE-BOOM-MET-BORG-125-150 CM | K13: 08-12-2025, 16:00, AMSTERDAM, DENK, Monday, Pickup Order, WAKE-UP | M13: Amsterdam Dille & Kamille - BB met kluit (incl. €10 borg) | O13: Line Item | P13: 32699820998979 | S13: Machiel | T13: Spruijt | U13: MET-125-150
